#VRML_SIM R2020a utf8
WorldInfo {
  info [
    ""
  ]
}
Viewpoint {
  orientation -0.5861283450951631 0.5615904907598496 0.5840117154339602 2.1046451167717546
  position -0.14551264941214548 4.583348369005328 0.003233871383687692
}
TexturedBackground {
}
TexturedBackgroundLight {
}
RectangleArena {
  floorSize 1 3
}
Solid {
  translation 0 0.01 0
  children [
    DEF GROUND Shape {
      appearance PBRAppearance {
        metalness 0
      }
      geometry Box {
        size 1 0.02 3
      }
    }
  ]
  boundingObject USE GROUND
  recognitionColors [
    0 0 0
  ]
}
Robot {
  translation 0.12 0.06 -1.4
  children [
    Pen {
      translation 0 -0.02 0.02
      rotation 0 1 0 1.57
      children [
        Shape {
          appearance PBRAppearance {
            baseColor 1 0.666667 1
            metalness 0
          }
          geometry Cylinder {
            height 0.01
            radius 0.004
          }
        }
      ]
      inkDensity 1
      leadSize 0.005
    }
    DistanceSensor {
      translation -0.02 0 0.1
      rotation 0 1 0 -1.8708
      children [
        Shape {
          appearance PBRAppearance {
            baseColor 1 0 1
            metalness 0
          }
          geometry Box {
            size 0.01 0.01 0.01
          }
        }
      ]
      name "ds_right"
    }
    DistanceSensor {
      translation 0.02 0 0.1
      rotation 0 1 0 -1.2708
      children [
        Shape {
          appearance PBRAppearance {
            baseColor 1 0 1
            metalness 0
          }
          geometry Box {
            size 0.01 0.01 0.01
          }
        }
      ]
      name "ds_left"
    }
    DEF BODY Shape {
      appearance PBRAppearance {
        baseColor 1 0 0
        metalness 0
      }
      geometry Box {
        size 0.1 0.05 0.2
      }
    }
    HingeJoint {
      jointParameters HingeJointParameters {
        anchor 0.06 0 0.05
      }
      device [
        PositionSensor {
          name "front left position"
        }
        RotationalMotor {
          name "wheel1"
        }
      ]
      endPoint DEF WHEEL_FR Solid {
        translation 0.06 0 0.05
        rotation 0 0 1 1.5708
        children [
          DEF WHEEL Shape {
            appearance PBRAppearance {
              baseColor 1 1 0
              metalness 0
            }
            geometry Cylinder {
              height 0.02
              radius 0.04
            }
          }
        ]
        name "front left wheel"
        boundingObject USE WHEEL
        physics DEF WHEEL_PH Physics {
        }
      }
    }
    HingeJoint {
      jointParameters HingeJointParameters {
        anchor 0.06 0 -0.05
      }
      device [
        PositionSensor {
          name "back left position"
        }
        RotationalMotor {
          name "wheel3"
        }
      ]
      endPoint Solid {
        translation 0.06 0 -0.05
        rotation 0 0 1 1.5708
        children [
          DEF WHEEL Shape {
            appearance PBRAppearance {
              baseColor 1 1 0
              metalness 0
            }
            geometry Cylinder {
              height 0.02
              radius 0.04
            }
          }
        ]
        name "back left wheel"
        boundingObject USE WHEEL
        physics USE WHEEL_PH
      }
    }
    HingeJoint {
      jointParameters HingeJointParameters {
        anchor -0.06 0 0.05
      }
      device [
        PositionSensor {
          name "front right position"
        }
        RotationalMotor {
          name "wheel2"
        }
      ]
      endPoint Solid {
        translation -0.06 0 0.05
        rotation 0 0 1 1.5708
        children [
          DEF WHEEL Shape {
            appearance PBRAppearance {
              baseColor 1 1 0
              metalness 0
            }
            geometry Cylinder {
              height 0.02
              radius 0.04
            }
          }
        ]
        name "front right wheel"
        boundingObject USE WHEEL
        physics USE WHEEL_PH
      }
    }
    HingeJoint {
      jointParameters HingeJointParameters {
        anchor -0.06 0 -0.05
      }
      device [
        PositionSensor {
          name "back right position"
        }
        RotationalMotor {
          name "wheel4"
        }
      ]
      endPoint Solid {
        translation -0.06 0 -0.05
        rotation 0 0 1 1.5708
        children [
          DEF WHEEL Shape {
            appearance PBRAppearance {
              baseColor 1 1 0
              metalness 0
            }
            geometry Cylinder {
              height 0.02
              radius 0.04
            }
          }
        ]
        name "back right wheel"
        boundingObject USE WHEEL
        physics USE WHEEL_PH
      }
    }
  ]
  boundingObject USE BODY
  physics Physics {
  }
  controller "scribble"
}
